<?xml version="1.0"?>
<robot name="two_wheeled_robot" xmlns:xacro="http://ros.org/wiki/xacro">

  <!-- ****************** ROBOT CONSTANTS *******************************  -->
  <!-- Define the size of the robot's main chassis in meters -->
  <xacro:property name="base_width" value="0.39"/>
  <xacro:property name="base_length" value="0.70"/>
  <xacro:property name="base_height" value="0.20"/>
	
  <!-- Define the shape of the robot's two back wheels in meters -->
  <xacro:property name="wheel_radius" value="0.14"/>
  <xacro:property name="wheel_width" value="0.06"/>

  <!-- x-axis points forward, y-axis points to left, z-axis points upwards -->
  <!-- Define the gap between the wheel and chassis along y-axis in meters -->
  <xacro:property name="wheel_ygap" value="0.035"/>

  <!-- Position the wheels along the z-axis -->
  <xacro:property name="wheel_zoff" value="0.05"/>

  <!-- Position the wheels along the x-axis -->
  <xacro:property name="wheel_xoff" value="0.221"/>

  <!-- Position the caster wheel along the x-axis -->
  <xacro:property name="caster_xoff" value="0.217"/>

  <!-- Define intertial property macros  -->
  <xacro:macro name="box_inertia" params="m w h d">
    <inertial>
      <origin xyz="0 0 0" rpy="${pi/2} 0 ${pi/2}"/>
      <mass value="${m}"/>
      <inertia ixx="${(m/12) * (h*h + d*d)}" ixy="0.0" ixz="0.0" iyy="${(m/12) * (w*w + d*d)}" iyz="0.0" izz="${(m/12) * (w*w + h*h)}"/>
    </inertial>
  </xacro:macro>

  <xacro:macro name="cylinder_inertia" params="m r h">
    <inertial>
      <origin xyz="0 0 0" rpy="${pi/2} 0 0" />
      <mass value="${m}"/>
      <inertia ixx="${(m/12) * (3*r*r + h*h)}" ixy = "0" ixz = "0" iyy="${(m/12) * (3*r*r + h*h)}" iyz = "0" izz="${(m/2) * (r*r)}"/>
    </inertial>
  </xacro:macro>

  <xacro:macro name="sphere_inertia" params="m r">
    <inertial>
      <mass value="${m}"/>
      <inertia ixx="${(2/5) * m * (r*r)}" ixy="0.0" ixz="0.0" iyy="${(2/5) * m * (r*r)}" iyz="0.0" izz="${(2/5) * m * (r*r)}"/>
    </inertial>
  </xacro:macro>
  
  <!-- ********************** ROBOT BASE *********************************  -->
  <link name="base_link">
    <visual>
      <origin xyz="0 0 -0.05" rpy="1.5707963267949 0 3.141592654"/>
      <geometry>
        <mesh filename="file://$(find my_robot)/meshes/robot_base.stl" />
      </geometry>
      <material name="Red">
        <color rgba="1.0 0.0 0.0 1.0"/>
      </material>
    </visual>

    <collision>
      <geometry>
        <box size="${base_length} ${base_width} ${base_height}"/>
      </geometry>
    </collision>

    <xacro:box_inertia m="15.0" w="${base_width}" d="${base_length}" h="${base_height}"/>
  </link>

  <gazebo reference="base_link">
    <material>Gazebo/Red</material>
  </gazebo>

  
  <!-- ****************** ROBOT BASE FOOTPRINT ***************************  -->
  <!-- Define the center of the main robot chassis projected on the ground -->	
  <link name="base_footprint">
  	<xacro:box_inertia m="0" w="0" d="0" h="0"/>
  </link>

  <!-- The base footprint of the robot is located underneath the chassis -->
  <joint name="base_joint" type="fixed">
    <parent link="base_link"/>
    <child link="base_footprint"/>
    <origin xyz="0.0 0.0 ${-(wheel_radius+wheel_zoff)}" rpy="0 0 0"/>
  </joint>

  <!-- *********************** DRIVE WHEELS ******************************  -->
  <xacro:property name="x_reflect" value="-1"/>
  <xacro:property name="y_reflect" value="-1"/>
  
<!-- LEFT wheel -->
<link name="drivewhl_l_link">
  <visual>
    <origin xyz="0 0 0" rpy="${pi/2} 0 0"/>
    <geometry>
      <cylinder radius="${wheel_radius}" length="${wheel_width}"/>
    </geometry>
    <material name="Gray">
      <color rgba="0.5 0.5 0.5 1.0"/>
    </material>
  </visual>
  <collision>
    <origin xyz="0 0 0" rpy="${pi/2} 0 0"/> 
    <geometry>
      <cylinder radius="${wheel_radius}" length="${wheel_width}"/>
    </geometry>
  </collision>
  <xacro:cylinder_inertia m="0.5" r="${wheel_radius}" h="${wheel_width}"/>
</link>

<joint name="drivewhl_l_joint" type="continuous">
  <parent link="base_link"/>
  <child link="drivewhl_l_link"/>
  <origin xyz="${-wheel_xoff} ${base_width/2 + wheel_ygap} ${-wheel_zoff}" rpy="0 0 0"/>
  <axis xyz="0 1 0"/>
</joint>


<!-- RIGHT wheel -->
<link name="drivewhl_r_link">
  <visual>
    <origin xyz="0 0 0" rpy="${pi/2} 0 0"/>
    <geometry>
      <cylinder radius="${wheel_radius}" length="${wheel_width}"/>
    </geometry>
    <material name="Gray">
      <color rgba="0.5 0.5 0.5 1.0"/>
    </material>
  </visual>
  <collision>
    <origin xyz="0 0 0" rpy="${pi/2} 0 0"/> 
    <geometry>
      <cylinder radius="${wheel_radius}" length="${wheel_width}"/>
    </geometry>
  </collision>
  <xacro:cylinder_inertia m="0.5" r="${wheel_radius}" h="${wheel_width}"/>
</link>

<joint name="drivewhl_r_joint" type="continuous">
  <parent link="base_link"/>
  <child link="drivewhl_r_link"/>
  <origin xyz="${-wheel_xoff} ${-(base_width/2 + wheel_ygap)} ${-wheel_zoff}" rpy="0 0 0"/>
  <axis xyz="0 1 0"/>
</joint>

  <!-- Instantiate two wheels using the macro we just made through the 
       xacro:wheel tags. We also define the parameters to have one wheel
       on both sides at the back of our robot (i.e. x_reflect=-1).
  <xacro:wheel prefix="drivewhl_l" x_reflect="-1" y_reflect="1" />
  <xacro:wheel prefix="drivewhl_r" x_reflect="-1" y_reflect="-1" /> -->

  <!-- *********************** CASTER WHEEL ******************************  -->
  <!-- We add a caster wheel. It will be modeled as sphere.
       We define the wheel’s geometry, material and the joint to connect it to 
       base_link at the appropriate location. -->
  <link name="front_caster">
    <visual>
      <geometry>
        <sphere radius="${(wheel_radius+wheel_zoff-(base_height/2))}"/>
      </geometry>
      <material name="Cyan">
        <color rgba="0 1.0 1.0 1.0"/>
      </material>
    </visual>

    <collision>
      <origin xyz="0 0 0" rpy="0 0 0"/>
      <geometry>
        <sphere radius="${(wheel_radius+wheel_zoff-(base_height/2))}"/>
      </geometry>
    </collision>

    <xacro:sphere_inertia m="0.5" r="${(wheel_radius+wheel_zoff-(base_height/2))}"/>
  </link>
  
  <gazebo reference="front_caster">
    <mu1>0.01</mu1>
    <mu2>0.01</mu2>
    <material>Gazebo/White</material>
  </gazebo>

  <joint name="caster_joint" type="fixed">
    <parent link="base_link"/>
    <child link="front_caster"/>
    <origin xyz="${caster_xoff} 0.0 ${-(base_height/2)}" rpy="0 0 0"/>
  </joint>

  <!-- *********************** IMU SETUP *********************************  -->
  <!-- Each sensor must be attached to a link.                              --> 
  <link name="imu_link">
    <visual>
      <geometry>
        <box size="0.1 0.1 0.1"/>
      </geometry>
    </visual>
    
    <collision>
      <geometry>
        <box size="0.1 0.1 0.1"/>
      </geometry>
    </collision>
      
    <xacro:box_inertia m="0.1" w="0.1" d="0.1" h="0.1"/>
  </link>
    
  <joint name="imu_joint" type="fixed">
    <parent link="base_link"/>
    <child link="imu_link"/>
    <origin xyz="0 0 0.01"/>
  </joint>
    
  <gazebo reference="imu_link">
    <gravity>true</gravity>
    <sensor name="twr_imu" type="imu">
      <always_on>true</always_on>
      <update_rate>100</update_rate>
      <visualize>true</visualize>
      <topic>imu</topic>
      <gz_frame_id>imu_link</gz_frame_id>
      <imu>
        <orientation>
          <x>
            <noise type="gaussian">
              <mean>0.0</mean>
              <stddev>2e-3</stddev>
            </noise>
          </x>
          <y>
            <noise type="gaussian">
              <mean>0.0</mean>
              <stddev>2e-3</stddev>
            </noise>
          </y>
          <z>
            <noise type="gaussian">
              <mean>0.0</mean>
              <stddev>2e-3</stddev>
            </noise>
          </z>
        </orientation>
        <angular_velocity>
          <x>
            <noise type="gaussian">
              <mean>0.0</mean>
              <stddev>2e-4</stddev>
            </noise>
          </x>
          <y>
            <noise type="gaussian">
              <mean>0.0</mean>
              <stddev>2e-4</stddev>
            </noise>
          </y>
          <z>
            <noise type="gaussian">
              <mean>0.0</mean>
              <stddev>2e-4</stddev>
            </noise>
          </z>
        </angular_velocity>
        <linear_acceleration>
          <x>
            <noise type="gaussian">
              <mean>0.0</mean>
              <stddev>1.7e-2</stddev>
            </noise>
          </x>
          <y>
            <noise type="gaussian">
              <mean>0.0</mean>
              <stddev>1.7e-2</stddev>
            </noise>
          </y>
          <z>
            <noise type="gaussian">
              <mean>0.0</mean>
              <stddev>1.7e-2</stddev>
            </noise>
          </z>
        </linear_acceleration>
      </imu>
      <!-- made modifications to adapt to version of ros-->
      <plugin  filename="gz-sim-imu-system" name="gz::sim::systems::Imu">
      </plugin>
    </sensor>
</gazebo>

  <!-- *********************** LIDAR SETUP **********************************  -->
 <link name="lidar_link">
    <inertial>
      <origin xyz="0 0 0" rpy="0 0 0"/>
      <mass value="0.125"/>
      <inertia ixx="0.001"  ixy="0"  ixz="0" iyy="0.001" iyz="0" izz="0.001" />
    </inertial>

    <collision>
      <origin xyz="0 0 0" rpy="0 0 0"/>
      <geometry>
         <cylinder radius="0.0508" length="0.75"/>
      </geometry>
    </collision>

    <visual>
      <origin xyz="0 0 0" rpy="0 0 0"/>
      <geometry>
         <cylinder radius="0.0508" length="0.75"/>
      </geometry>
    </visual>
  </link>
    
  <joint name="lidar_joint" type="fixed">
    <parent link="base_link"/>
    <child link="lidar_link"/>
    <origin xyz="0.215 0.0 0.30" rpy="0 0 0"/>
  </joint>
    
  <gazebo reference="lidar_link">
    <sensor name="lidar" type="gpu_ray">
      <always_on>true</always_on>
      <visualize>true</visualize>
      <topic>scan</topic>
      <update_rate>5</update_rate>
      <gz_frame_id>lidar_link</gz_frame_id>
      <ray>
        <scan>
          <horizontal>
            <samples>360</samples>
            <resolution>1.000000</resolution>
            <min_angle>0</min_angle>
            <max_angle>6.28</max_angle>
          </horizontal>
        </scan>
        <range>
          <min>0.12</min>
          <max>12.0</max>
          <resolution>0.015</resolution>
        </range>
        <noise>
          <type>gaussian</type>
          <mean>0.0</mean>
          <stddev>0.01</stddev>
        </noise>
      </ray>
      <plugin name="gz::sim::systems::Sensors" filename="gz-sim-sensors-system">
        <render_engine>ogre2</render_engine>
      </plugin>

    </sensor>
  </gazebo>
  <gazebo reference="lidar_link">
    <mu1>0.01</mu1>
    <mu2>0.01</mu2>
    <material>Gazebo/Black</material>
  </gazebo>


 <!-- *********************** WHEEL ODOMETRY ***************************    --> 
 <gazebo>
  <plugin filename="gz-sim-diff-drive-system" name="gz::sim::systems::DiffDrive">
    
    <!-- Joint names (must match SDF model) -->
    <left_joint>drivewhl_l_joint</left_joint>
    <right_joint>drivewhl_r_joint</right_joint>

    <!-- Wheel separation and diameter -->
    <wheel_separation>0.52</wheel_separation>
    <wheel_radius>0.14</wheel_radius> <!-- Half of 0.28 diameter -->

    <!-- Update rate (optional) -->
    <update_rate>30</update_rate>

    <!-- Limits -->
    <max_torque>20</max_torque>
    <max_acceleration>1.0</max_acceleration>

    <!-- Command and odometry topics -->
    <topic>cmd_vel</topic>
    <odom_topic>odom</odom_topic>

    <!-- Frame names -->
    <odom_frame>odom</odom_frame>
    <base_frame>base_link</base_frame>

    <!-- Publish odometry -->
    <publish_odom>true</publish_odom>
    <publish_tf>true</publish_tf>

  </plugin>
</gazebo>

</robot>