<?xml version="1.0"?>
<robot xmlns:xacro="http://ros.org/wiki/xacro">
 
  <xacro:include filename="$(find my_robot)/parts/prop/property.xacro"/>
  
   <xacro:macro name="diff_wheel">
  <xacro:macro name="wheels" params="prefix x_reflect y_reflect">
   
    <link name="${prefix}_link">
      <visual>
        <origin xyz="0 0 0" rpy="${pi/2} 0 0"/>
        <geometry>
            <cylinder radius="${wheel_radius}" length="${wheel_width}"/>
        </geometry>
        <material name="Gray">
          <color rgba="0.5 0.5 0.5 1.0"/>
        </material>
      </visual>

      <collision>
        <origin xyz="0 0 0" rpy="${pi/2} 0 0"/> 
        <geometry>
          <cylinder radius="${wheel_radius}" length="${wheel_width}"/>
        </geometry>
      </collision>

      <xacro:cylinder_inertia m="0.5" r="${wheel_radius}" h="${wheel_width}"/>
    </link>

    <!-- Connect the wheels to the base_link at the appropriate location, and 
         define a continuous joint to allow the wheels to freely rotate about
         an axis -->
    <joint name="${prefix}_joint" type="continuous">
      <parent link="base_link"/>
      <child link="${prefix}_link"/>
      <origin xyz="${x_reflect*wheel_xoff} ${y_reflect*(base_width/2+wheel_ygap)} ${-wheel_zoff}" rpy="0 0 0"/>
      <axis xyz="0 1 0"/>
    </joint>
  </xacro:macro>

  <xacro:wheels prefix="drivewhl_l" x_reflect="-1" y_reflect="1" />
  <xacro:wheels prefix="drivewhl_r" x_reflect="-1" y_reflect="-1" />
</xacro:macro>
  
</robot>
